Workbook
Name Slicer_Category: #N/A
Name Slicer_Customer_Segment: #N/A
Name Slicer_Region: #N/A
Name Slicer_Sales_Channel: #N/A

Sheet Raw_Data
A1: Order_ID | B1: Order_Date | C1: Customer_ID | D1: Customer_Name | E1: Customer_Segment | F1: City | G1: State | H1: Region | I1: Category | J1: Product | K1: Quantity | L1: Unit_Price | M1: Discount | N1: Sales | O1: Cost | P1: Profit | Q1: Profit_Margin_% | R1: Payment_Method | S1: Sales_Channel | T1: Salesperson | U1: Month | V1: Year | W1: Day_Name | X1: Delivery_Days | Y1: Delivery_Date | Z1: Order_Status | AA1: Customer_Type | AB1: Priority | AC1: Return_Requested | AD1: Rating | AE1: Column1
A2: ORD10002 | B2: 14-04-2024 | C2: CUST1017 | D2: Aarav Verma | E2: Consumer | F2: Mumbai | G2: Maharashtra | H2: South | I2: Electronics | J2: Tablet | K2: 4 | L2: 12000 | M2: 0.05 | N2: 45600 | O2: 32350.14 | P2: 13249.86 | Q2: 29.06 | R2: Net Banking | S2: Marketplace | T2: Amit | U2: April | V2: 2024 | W2: Sunday | X2: 9 | Y2: 23-04-2024 | Z2: Completed | AA2: VIP | AB2: Low | AC2: No | AD2: 2
A3: ORD10003 | B3: 14-12-2024 | C3: CUST1173 | D3: Arjun Verma | E3: Corporate | F3: Jaipur | G3: Rajasthan | H3: North | I3: Accessories | J3: Wallet | K3: 1 | L3: 800 | M3: 0.15 | N3: 680 | O3: 413.53 | P3: 266.47 | Q3: 39.19 | R3: UPI | S3: Retail Store | T3: Manish | U3: December | V3: 2024 | W3: Saturday | X3: 5 | Y3: 19-12-2024 | Z3: Completed | AA3: Returning | AB3: Low | AC3: No | AD3: 5
A4: ORD10004 | B4: 45778 | C4: CUST1024 | D4: Vikram Agarwal | E4: Corporate | F4: Mumbai | G4: Maharashtra | H4: North | I4: Clothing | J4: Shirt | K4: 9 | L4: 1800 | M4: 0.2 | N4: 12960 | O4: 9593.44 | P4: 3366.56 | Q4: 25.98 | R4: Debit Card | S4: Online | T4: Kavita | U4: January | V4: 2025 | W4: Sunday | X4: 10 | Y4: 15-01-2025 | Z4: Completed | AA4: Returning | AB4: Medium | AC4: No | AD4: 2
A5: ORD10005 | B5: 46001 | C5: CUST1084 | D5: Riya Mehta | E5: Corporate | F5: Chennai | G5: Tamil Nadu | H5: South | I5: Office Supplies | J5: Printer Paper | K5: 5 | L5: 100 | M5: 0.2 | N5: 400 | O5: 298.75 | P5: 101.25 | Q5: 25.31 | R5: UPI | S5: Online | T5: Rahul | U5: October | V5: 2025 | W5: Sunday | X5: 3 | Y5: 15-10-2025 | Z5: Cancelled | AA5: New | AB5: Medium | AC5: No | AD5: 3
A6: ORD10006 | B6: 45902 | C6: CUST1127 | D6: Aditi Kapoor | E6: Corporate | F6: Mumbai | G6: Maharashtra | H6: West | I6: Furniture | J6: Table | K6: 6 | L6: 4000 | M6: 0.15 | N6: 20400 | O6: 12678.96 | P6: 7721.04 | Q6: 37.85 | R6: Net Banking | S6: Retail Store | T6: Vikas | U6: February | V6: 2025 | W6: Sunday | X6: 8 | Y6: 17-02-2025 | Z6: Completed | AA6: New | AB6: Low | AC6: No | AD6: 1
A7: ORD10007 | B7: 45697 | C7: CUST1240 | D7: Meera Kumar | E7: Small Business | F7: Delhi | G7: Delhi | H7: North | I7: Electronics | J7: Smartphone | K7: 3 | L7: 50000 | M7: 0.15 | N7: 127500 | O7: 83262.24 | P7: 44237.76 | Q7: 34.7 | R7: Credit Card | S7: Marketplace | T7: Anjali | U7: September | V7: 2025 | W7: Tuesday | X7: 2 | Y7: 45756 | Z7: Pending | AA7: Returning | AB7: High | AC7: No | AD7: 1
A8: ORD10008 | B8: 27-05-2025 | C8: CUST1321 | D8: Priya Chopra | E8: Small Business | F8: Pune | G8: Maharashtra | H8: South | I8: Clothing | J8: Jeans | K8: 8 | L8: 700 | M8: 0.1 | N8: 5040 | O8: 4013.9 | P8: 1026.1 | Q8: 20.36 | R8: Debit Card | S8: Retail Store | T8: Pooja | U8: May | V8: 2025 | W8: Tuesday | X8: 3 | Y8: 30-05-2025 | Z8: Cancelled | AA8: VIP | AB8: High | AC8: Yes | AD8: 5 | AE8: a
A9: ORD10009 | B9: 45331 | C9: CUST1041 | D9: Aditya Yadav | E9: Corporate | F9: Chennai | G9: Tamil Nadu | H9: North | I9: Clothing | J9: Shirt | K9: 2 | L9: 1800 | M9: 0.1 | N9: 3240 | O9: 2550.08 | P9: 689.92 | Q9: 21.29 | R9: Net Banking | S9: Online | T9: Pooja | U9: September | V9: 2024 | W9: Monday | X9: 1 | Y9: 45360 | Z9: Completed | AA9: VIP | AB9: Medium | AC9: Yes | AD9: 3
A10: ORD10010 | B10: 31-12-2025 | C10: CUST1333 | D10: Sneha Malhotra | E10: Small Business | F10: Ahmedabad | G10: Gujarat | H10: West | I10: Accessories | J10: Sunglasses | K10: 4 | L10: 3000 | M10: 0.05 | N10: 11400 | O10: 9333.07 | P10: 2066.93 | Q10: 18.13 | R10: Credit Card | S10: Online | T10: Rahul | U10: December | V10: 2025 | W10: Wednesday | X10: 5 | Y10: 46143 | Z10: Pending | AA10: New | AB10: Medium | AC10: Yes | AD10: 5
A11: ORD10011 | B11: 25-12-2025 | C11: CUST1017 | D11: Neha Verma | E11: Small Business | F11: Ahmedabad | G11: Gujarat | H11: South | I11: Furniture | J11: Table | K11: 4 | L11: 2500 | M11: 0 | N11: 10000 | O11: 5681.98 | P11: 4318.02 | Q11: 43.18 | R11: UPI | S11: Marketplace | T11: Rohit | U11: December | V11: 2025 | W11: Thursday | X11: 1 | Y11: 26-12-2025 | Z11: Completed | AA11: New | AB11: High | AC11: Yes | AD11: 5
A12: ORD10012 | B12: 45447 | C12: CUST1211 | D12: Riya Chopra | E12: Small Business | F12: Lucknow | G12: Uttar Pradesh | H12: North | I12: Clothing | J12: Jeans | K12: 8 | L12: 2500 | M12: 0.05 | N12: 19000 | O12: 12267.55 | P12: 6732.45 | Q12: 35.43 | R12: Credit Card | S12: Online | T12: Kavita | U12: April | V12: 2024 | W12: Saturday | X12: 2 | Y12: 45508 | Z12: Pending | AA12: VIP | AB12: Medium | AC12: Yes | AD12: 2
A13: ORD10013 | B13: 45450 | C13: CUST1039 | D13: Riya Agarwal | E13: Small Business | F13: Hyderabad | G13: Telangana | H13: North | I13: Furniture | J13: Table | K13: 8 | L13: 4000 | M13: 0.15 | N13: 27200 | O13: 16794.58 | P13: 10405.42 | Q13: 38.26 | R13: Credit Card | S13: Marketplace | T13: Anjali | U13: July | V13: 2024 | W13: Saturday | X13: 5 | Y13: 45603 | Z13: Pending | AA13: New | AB13: Low | AC13: Yes | AD13: 2
A14: ORD10014 | B14: 17-06-2024 | C14: CUST1136 | D14: Riya Kumar | E14: Corporate | F14: Kolkata | G14: West Bengal | H14: West | I14: Clothing | J14: Shoes | K14: 4 | L14: 2500 | M14: 0 | N14: 10000 | O14: 8160.33 | P14: 1839.67 | Q14: 18.4 | R14: Debit Card | S14: Online | T14: Sneha | U14: June | V14: 2024 | W14: Monday | X14: 7 | Y14: 24-06-2024 | Z14: Completed | AA14: New | AB14: Low | AC14: Yes | AD14: 3
A15: ORD10015 | B15: 45571 | C15: CUST1096 | D15: Aditya Bansal | E15: Consumer | F15: Delhi | G15: Delhi | H15: South | I15: Electronics | J15: Monitor | K15: 8 | L15: 35000 | M15: 0.2 | N15: 224000 | O15: 128045.14 | P15: 95954.86 | Q15: 42.84 | R15: Cash | S15: Online | T15: Manish | U15: June | V15: 2024 | W15: Monday | X15: 1 | Y15: 45602 | Z15: Cancelled | AA15: New | AB15: High | AC15: Yes | AD15: 5
A16: ORD10016 | B16: 24-09-2024 | C16: CUST1203 | D16: Rohan Mishra | E16: Small Business | F16: Mumbai | G16: Maharashtra | H16: East | I16: Clothing | J16: T-Shirt | K16: 10 | L16: 3500 | M16: 0.1 | N16: 31500 | O16: 19355.02 | P16: 12144.98 | Q16: 38.56 | R16: Cash | S16: Retail Store | T16: Neeraj | U16: September | V16: 2024 | W16: Tuesday | X16: 4 | Y16: 28-09-2024 | Z16: Completed | AA16: New | AB16: Medium | AC16: Yes | AD16: 1
A17: ORD10017 | B17: 45599 | C17: CUST1225 | D17: Aditi Yadav | E17: Corporate | F17: Ahmedabad | G17: Gujarat | H17: North | I17: Furniture | J17: Table | K17: 5 | L17: 4000 | M17: 0.1 | N17: 18000 | O17: 11285.04 | P17: 6714.96 | Q17: 37.31 | R17: Net Banking | S17: Retail Store | T17: Neeraj | U17: March | V17: 2024 | W17: Monday | X17: 4 | Y17: 15-03-2024 | Z17: Completed | AA17: New | AB17: Medium | AC17: Yes | AD17: 1
A18: ORD10018 | B18: 17-12-2024 | C18: CUST1129 | D18: Vivaan Verma | E18: Small Business | F18: Ahmedabad | G18: Gujarat | H18: West | I18: Furniture | J18: Bookshelf | K18: 5 | L18: 15000 | M18: 0.05 | N18: 71250 | O18: 48910.31 | P18: 22339.69 | Q18: 31.35 | R18: UPI | S18: Online | T18: Amit | U18: December | V18: 2024 | W18: Tuesday | X18: 4 | Y18: 21-12-2024 | Z18: Completed | AA18: Returning | AB18: Low | AC18: No | AD18: 2
A19: ORD10019 | B19: 18-03-2024 | C19: CUST1190 | D19: Nisha Kapoor | E19: Consumer | F19: Jaipur | G19: Rajasthan | H19: West | I19: Accessories | J19: Sunglasses | K19: 9 | L19: 500 | M19: 0 | N19: 4500 | O19: 2518.77 | P19: 1981.23 | Q19: 44.03 | R19: Debit Card | S19: Online | T19: Sneha | U19: March | V19: 2024 | W19: Monday | X19: 3 | Y19: 21-03-2024 | Z19: Cancelled | AA19: Returning | AB19: Low | AC19: No | AD19: 2
A20: ORD10020 | B20: 45479 | C20: CUST1091 | D20: Ishita Sharma | E20: Consumer | F20: Hyderabad | G20: Telangana | H20: East | I20: Electronics | J20: Tablet | K20: 9 | L20: 22000 | M20: 0.2 | N20: 158400 | O20: 128870.38 | P20: 29529.62 | Q20: 18.64 | R20: Cash | S20: Marketplace | T20: Rahul | U20: June | V20: 2024 | W20: Friday | X20: 4 | Y20: 45602 | Z20: Completed | AA20: Returning | AB20: Low | AC20: Yes | AD20: 4
A21: ORD10021 | B21: 45515 | C21: CUST1099 | D21: Pooja Jain | E21: Corporate | F21: Delhi | G21: Delhi | H21: North | I21: Clothing | J21: Jeans | K21: 4 | L21: 2500 | M21: 0.1 | N21: 9000 | O21: 5007.5 | P21: 3992.5 | Q21: 44.36 | R21: UPI | S21: Retail Store | T21: Anjali | U21: November | V21: 2024 | W21: Friday | X21: 4 | Y21: 45637 | Z21: Completed | AA21: Returning | AB21: High | AC21: No | AD21: 1
A22: ORD10022 | B22: 21-04-2024 | C22: CUST1161 | D22: Ishita Bansal | E22: Small Business | F22: Mumbai | G22: Maharashtra | H22: North | I22: Office Supplies | J22: Printer Paper | K22: 10 | L22: 350 | M22: 0 | N22: 3500 | O22: 2251.67 | P22: 1248.33 | Q22: 35.67 | R22: Cash | S22: Marketplace | T22: Rahul | U22: April | V22: 2024 | W22: Sunday | X22: 10 | Y22: 45296 | Z22: Pending | AA22: Returning | AB22: Low | AC22: No | AD22: 1
A23: ORD10023 | B23: 45972 | C23: CUST1064 | D23: Priya Kapoor | E23: Corporate | F23: Ahmedabad | G23: Gujarat | H23: West | I23: Accessories | J23: Watch | K23: 6 | L23: 2000 | M23: 0 | N23: 12000 | O23: 7617.09 | P23: 4382.91 | Q23: 36.52 | R23: UPI | S23: Retail Store | T23: Sneha | U23: November | V23: 2025 | W23: Tuesday | X23: 6 | Y23: 17-11-2025 | Z23: Cancelled | AA23: VIP | AB23: Low | AC23: Yes | AD23: 4
A24: ORD10024 | B24: 15-07-2025 | C24: CUST1221 | D24: Nisha Bansal | E24: Small Business | F24: Kolkata | G24: West Bengal | H24: East | I24: Furniture | J24: Table | K24: 10 | L24: 6000 | M24: 0.15 | N24: 51000 | O24: 32000.8 | P24: 18999.2 | Q24: 37.25 | R24: Cash | S24: Retail Store | T24: Rohit | U24: July | V24: 2025 | W24: Tuesday | X24: 1 | Y24: 16-07-2025 | Z24: Completed | AA24: VIP | AB24: Low | AC24: No | AD24: 2
A25: ORD10025 | B25: 28-08-2024 | C25: CUST1076 | D25: Aarav Sharma | E25: Consumer | F25: Mumbai | G25: Maharashtra | H25: West | I25: Office Supplies | J25: Stapler | K25: 10 | L25: 350 | M25: 0 | N25: 3500 | O25: 2687.2 | P25: 812.8 | Q25: 23.22 | R25: Net Banking | S25: Online | T25: Rohit | U25: August | V25: 2024 | W25: Wednesday | X25: 5 | Y25: 45331 | Z25: Completed | AA25: Returning | AB25: High | AC25: Yes | AD25: 4
A26: ORD10026 | B26: 45964 | C26: CUST1266 | D26: Riya Sharma | E26: Small Business | F26: Jaipur | G26: Rajasthan | H26: South | I26: Clothing | J26: Jeans | K26: 3 | L26: 700 | M26: 0 | N26: 2100 | O26: 1610.93 | P26: 489.07 | Q26: 23.29 | R26: Credit Card | S26: Retail Store | T26: Pooja | U26: March | V26: 2025 | W26: Tuesday | X26: 4 | Y26: 15-03-2025 | Z26: Completed | AA26: Returning | AB26: High | AC26: No | AD26: 4
A27: ORD10027 | B27: 45662 | C27: CUST1327 | D27: Ananya Agarwal | E27: Small Business | F27: Lucknow | G27: Uttar Pradesh | H27: West | I27: Accessories | J27: Sunglasses | K27: 9 | L27: 2000 | M27: 0.05 | N27: 17100 | O27: 12875.95 | P27: 4224.05 | Q27: 24.7 | R27: Debit Card | S27: Retail Store | T27: Rohit | U27: May | V27: 2025 | W27: Thursday | X27: 8 | Y27: 45905 | Z27: Completed | AA27: New | AB27: High | AC27: No | AD27: 2
A28: ORD10028 | B28: 45357 | C28: CUST1110 | D28: Aditya Mehta | E28: Corporate | F28: Pune | G28: Maharashtra | H28: East | I28: Office Supplies | J28: Pen Set | K28: 9 | L28: 100 | M28: 0.05 | N28: 855 | O28: 630.45 | P28: 224.55 | Q28: 26.26 | R28: Net Banking | S28: Retail Store | T28: Kavita | U28: June | V28: 2024 | W28: Monday | X28: 4 | Y28: 45479 | Z28: Pending | AA28: New | AB28: Low | AC28: No | AD28: 4
A29: ORD10029 | B29: 26-12-2024 | C29: CUST1215 | D29: Aditi Yadav | E29: Small Business | F29: Lucknow | G29: Uttar Pradesh | H29: South | I29: Electronics | J29: Monitor | K29: 7 | L29: 22000 | M29: 0 | N29: 154000 | O29: 120186.37 | P29: 33813.63 | Q29: 21.96 | R29: Cash | S29: Online | T29: Sneha | U29: December | V29: 2024 | W29: Thursday | X29: 5 | Y29: 31-12-2024 | Z29: Pending | AA29: Returning | AB29: Medium | AC29: Yes | AD29: 4
A30: ORD10030 | B30: 30-06-2025 | C30: CUST1340 | D30: Aarav Verma | E30: Small Business | F30: Chennai | G30: Tamil Nadu | H30: West | I30: Clothing | J30: Jeans | K30: 8 | L30: 1200 | M30: 0.2 | N30: 7680 | O30: 5451.35 | P30: 2228.65 | Q30: 29.02 | R30: Debit Card | S30: Retail Store | T30: Pooja | U30: June | V30: 2025 | W30: Monday | X30: 1 | Y30: 45664 | Z30: Pending | AA30: New | AB30: Medium | AC30: No | AD30: 3
A31: ORD10031 | B31: 45841 | C31: CUST1277 | D31: Vivaan Jain | E31: Consumer | F31: Hyderabad | G31: Telangana | H31: North | I31: Clothing | J31: Jacket | K31: 6 | L31: 2500 | M31: 0.1 | N31: 13500 | O31: 9139.27 | P31: 4360.73 | Q31: 32.3 | R31: Credit Card | S31: Online | T31: Rahul | U31: March | V31: 2025 | W31: Friday | X31: 5 | Y31: 45994 | Z31: Completed | AA31: New | AB31: Low | AC31: Yes | AD31: 2
A32: ORD10032 | B32: 17-12-2025 | C32: CUST1311 | D32: Arjun Agarwal | E32: Consumer | F32: Bengaluru | G32: Karnataka | H32: East | I32: Clothing | J32: Shirt | K32: 10 | L32: 1200 | M32: 0.15 | N32: 10200 | O32: 6072.09 | P32: 4127.91 | Q32: 40.47 | R32: Credit Card | S32: Marketplace | T32: Amit | U32: December | V32: 2025 | W32: Wednesday | X32: 5 | Y32: 22-12-2025 | Z32: Completed | AA32: Returning | AB32: High | AC32: No | AD32: 4
A33: ORD10033 | B33: 45669 | C33: CUST1290 | D33: Vivaan Jain | E33: Small Business | F33: Hyderabad | G33: Telangana | H33: West | I33: Electronics | J33: Monitor | K33: 4 | L33: 8000 | M33: 0.1 | N33: 28800 | O33: 22031.46 | P33: 6768.54 | Q33: 23.5 | R33: UPI | S33: Online | T33: Anjali | U33: December | V33: 2025 | W33: Monday | X33: 10 | Y33: 45973 | Z33: Completed | AA33: VIP | AB33: Medium | AC33: Yes | AD33: 4
A34: ORD10034 | B34: 25-12-2025 | C34: CUST1268 | D34: Ananya Bansal | E34: Small Business | F34: Jaipur | G34: Rajasthan | H34: West | I34: Electronics | J34: Headphones | K34: 6 | L34: 50000 | M34: 0.15 | N34: 255000 | O34: 152377.03 | P34: 102622.97 | Q34: 40.24 | R34: Cash | S34: Retail Store | T34: Manish | U34: December | V34: 2025 | W34: Thursday | X34: 3 | Y34: 28-12-2025 | Z34: Pending | AA34: Returning | AB34: Medium | AC34: Yes | AD34: 1
A35: ORD10035 | B35: 15-11-2025 | C35: CUST1167 | D35: Karan Malhotra | E35: Consumer | F35: Pune | G35: Maharashtra | H35: East | I35: Clothing | J35: Jeans | K35: 8 | L35: 3500 | M35: 0.2 | N35: 22400 | O35: 12493.58 | P35: 9906.42 | Q35: 44.23 | R35: UPI | S35: Retail Store | T35: Sneha | U35: November | V35: 2025 | W35: Saturday | X35: 7 | Y35: 22-11-2025 | Z35: Completed | AA35: VIP | AB35: High | AC35: No | AD35: 5
A36: ORD10036 | B36: 15-05-2025 | C36: CUST1331 | D36: Kavya Malhotra | E36: Consumer | F36: Delhi | G36: Delhi | H36: North | I36: Accessories | J36: Watch | K36: 2 | L36: 800 | M36: 0.15 | N36: 1360 | O36: 1001.59 | P36: 358.41 | Q36: 26.35 | R36: UPI | S36: Online | T36: Kavita | U36: May | V36: 2025 | W36: Thursday | X36: 9 | Y36: 24-05-2025 | Z36: Completed | AA36: VIP | AB36: Low | AC36: No | AD36: 5
A37: ORD10037 | B37: 17-07-2025 | C37: CUST1139 | D37: Priya Kumar | E37: Consumer | F37: Chennai | G37: Tamil Nadu | H37: North | I37: Clothing | J37: T-Shirt | K37: 9 | L37: 1800 | M37: 0.15 | N37: 13770 | O37: 10186.64 | P37: 3583.36 | Q37: 26.02 | R37: Debit Card | S37: Retail Store | T37: Neeraj | U37: July | V37: 2025 | W37: Thursday | X37: 6 | Y37: 23-07-2025 | Z37: Completed | AA37: VIP | AB37: High | AC37: Yes | AD37: 2
A38: ORD10038 | B38: 16-10-2024 | C38: CUST1185 | D38: Karan Kumar | E38: Consumer | F38: Hyderabad | G38: Telangana | H38: South | I38: Clothing | J38: Jacket | K38: 10 | L38: 3500 | M38: 0.2 | N38: 28000 | O38: 17639.62 | P38: 10360.38 | Q38: 37 | R38: UPI | S38: Online | T38: Amit | U38: October | V38: 2024 | W38: Wednesday | X38: 2 | Y38: 18-10-2024 | Z38: Completed | AA38: VIP | AB38: Medium | AC38: Yes | AD38: 4
A39: ORD10039 | B39: 27-03-2025 | C39: CUST1130 | D39: Kavya Verma | E39: Consumer | F39: Mumbai | G39: Maharashtra | H39: West | I39: Electronics | J39: Monitor | K39: 5 | L39: 22000 | M39: 0.15 | N39: 93500 | O39: 75798.99 | P39: 17701.01 | Q39: 18.93 | R39: Cash | S39: Online | T39: Manish | U39: March | V39: 2025 | W39: Thursday | X39: 6 | Y39: 45692 | Z39: Completed | AA39: VIP | AB39: High | AC39: Yes | AD39: 2
A40: ORD10040 | B40: 25-07-2025 | C40: CUST1317 | D40: Vikram Agarwal | E40: Small Business | F40: Bengaluru | G40: Karnataka | H40: West | I40: Accessories | J40: Wallet | K40: 2 | L40: 800 | M40: 0 | N40: 1600 | O40: 1137.53 | P40: 462.47 | Q40: 28.9 | R40: Cash | S40: Retail Store | T40: Sneha | U40: July | V40: 2025 | W40: Friday | X40: 7 | Y40: 45665 | Z40: Cancelled | AA40: VIP | AB40: Medium | AC40: No | AD40: 5
...

Sheet Sheet2
A3: Region | B3: Sum of Sales
A4: East | B4: 7518642.5
A5: North | B5: 5965332.5
A6: South | B6: 8560317.5
A7: West | B7: 8266957.5
A8: Grand Total | B8: 30311250

Sheet Sheet3
A3: Category | B3: Sum of Sales
A4: Accessories | B4: 1466745
A5: Clothing | B5: 1886370
A6: Electronics | B6: 19767000
A7: Furniture | B7: 6779800
A8: Office Supplies | B8: 411335
A9: Grand Total | B9: 30311250

Sheet Sheet4
A3: Product | B3: Sum of Sales
A4: Backpack | B4: 381040
A5: Belt | B5: 331880
A6: Bookshelf | B6: 1141650
A7: Desk | B7: 1791875
A8: File Folder | B8: 64612.5
A9: Headphones | B9: 2740850
A10: Jacket | B10: 420105
A11: Jeans | B11: 319065
A12: Laptop | B12: 3513350
A13: Monitor | B13: 4066900
A14: Notebook | B14: 84285
A15: Office Chair | B15: 1289950
... A29: Grand Total | B29: 30311250

Sheet Sheet6
A3: Month | B3: Sum of Sales
A4: January | B4: 1889497.5
A5: February | B5: 2361560
A6: March | B6: 2618520
A7: April | B7: 1803637.5
A8: May | B8: 1121067.5
A9: June | B9: 2765790
A10: July | B10: 3495020
A11: August | B11: 2480745
A12: September | B12: 3190750
A13: October | B13: 3112707.5
A14: November | B14: 2076795
A15: December | B15: 3395160
A16: Grand Total | B16: 30311250

Sheet Sheet7
A3: Salesperson | B3: Sum of Sales
A4: Amit | B4: 3295187.5
A5: Anjali | B5: 2952162.5
A6: Kavita | B6: 3337090
A7: Manish | B7: 3934230
A8: Neeraj | B8: 2937487.5
A9: Pooja | B9: 2963150
A10: Rahul | B10: 2934365
A11: Rohit | B11: 3031592.5
A12: Sneha | B12: 2992322.5
A13: Vikas | B13: 1933662.5
A14: Grand Total | B14: 30311250

Sheet Sheet8
A3: Customer_Segment | B3: Sum of Sales
A4: Consumer | B4: 10446645
A5: Corporate | B5: 10315895
A6: Small Business | B6: 9548710
A7: Grand Total | B7: 30311250

Sheet Sheet9
A3: Payment_Method | B3: Sum of Sales
A4: Cash | B4: 7422207.5
A5: Credit Card | B5: 5132640
A6: Debit Card | B6: 5321137.5
A7: Net Banking | B7: 7103552.5
A8: UPI | B8: 5331712.5
A9: Grand Total | B9: 30311250

Sheet Sheet10
A3: Order_Status | B3: Sum of Sales
A4: Cancelled | B4: 5967697.5
A5: Completed | B5: 17792045
A6: Pending | B6: 6551507.5
A7: Grand Total | B7: 30311250

Sheet Sheet5
A3: Category | B3: Sum of Profit2 | C3: Sum of Profit
A4: Electronics | B4: 1065908.1 | C4: 1065908.1
A5: Furniture | B5: 481396.74 | C5: 481396.74
A6: Clothing | B6: 153730.63 | C6: 153730.63
A7: Accessories | B7: 104830.38 | C7: 104830.38
A8: Office Supplies | B8: 38664.94 | C8: 38664.94
A9: Grand Total | B9: 1844530.8 | C9: 1844530.8

Sheet Detail1
A1: Details for Sum of Profit - Category: Clothing
A3: Order_ID | B3: Order_Date | C3: Customer_ID | D3: Customer_Name | E3: Customer_Segment | F3: City | G3: State | H3: Region | I3: Category | J3: Product | K3: Quantity | L3: Unit_Price | M3: Discount | N3: Sales | O3: Cost | P3: Profit | Q3: Profit_Margin_% | R3: Payment_Method | S3: Sales_Channel | T3: Salesperson | U3: Month | V3: Year | W3: Day_Name | X3: Delivery_Days | Y3: Delivery_Date | Z3: Order_Status | AA3: Customer_Type | AB3: Priority | AC3: Return_Requested | AD3: Rating | AE3: First_name | AF3: Last_Name | AG3: SUM | AH3: Average | AI3: Count | AJ3: Counta | AK3: MIN | AL3: Max | AM3: IF | AN3: IFS | AO3: AND | AP3: OR | AQ3: IFERROR | AR3: SUMIFS | AS3: COUNTIFS | AT3: AVERAGEIFS | AU3: Region-wise Sales | AV3: Category-wise Sales | AW3: Total Sales | AX3: Salesperson-wise Sales | AY3: Monthly Sales | AZ3: Year-wise Sales | BA3: Profit Analysis | BB3: Profit Margin Analysis | BC3: Discount Analysis | BD3: Region_Total_Sales | BE3: Product_wise Sales | BF3: Total Sales2
A4: ORD10524 | B4: 30-12-2024 | C4: CUST1258 | D4: Arjun Kapoor | E4: Consumer | F4: Pune | G4: Maharashtra | H4: North | I4: Clothing | J4: T-Shirt | K4: 4 | L4: 1800 | M4: 0.15 | N4: 6120 | O4: 3913.47 | P4: 2206.53 | Q4: 36.05 | R4: Net Banking | S4: Retail Store | T4: Rohit | U4: December | V4: 2024 | W4: Monday | X4: 3 | Y4: 45689 | Z4: Completed | AA4: VIP | AB4: Low | AC4: No | AD4: 2 | AE4: Arjun | AF4: Kapoor | AM4: Good | AN4: Low | AO4: No | AP4: No | AQ4: 0.36054412
A5: ORD10480 | B5: 27-10-2025 | C5: CUST1077 | D5: Pooja Singh | E5: Consumer | F5: Chennai | G5: Tamil Nadu | H5: North | I5: Clothing | J5: Jeans | K5: 1 | L5: 700 | M5: 0.2 | N5: 560 | O5: 373.59 | P5: 186.41 | Q5: 33.29 | R5: Debit Card | S5: Retail Store | T5: Rohit | U5: October | V5: 2025 | W5: Monday | X5: 6 | Y5: 45699 | Z5: Cancelled | AA5: Returning | AB5: High | AC5: Yes | AD5: 4 | AE5: Pooja | AF5: Singh | AM5: Good | AN5: Low | AO5: No | AP5: No | AQ5: 0.332875
A6: ORD10477 | B6: 45294 | C6: CUST1108 | D6: Vikram Yadav | E6: Small Business | F6: Lucknow | G6: Uttar Pradesh | H6: North | I6: Clothing | J6: Jeans | K6: 8 | L6: 1800 | M6: 0.15 | N6: 12240 | O6: 9467.99 | P6: 2772.01 | Q6: 22.65 | R6: Debit Card | S6: Retail Store | T6: Kavita | U6: March | V6: 2024 | W6: Friday | X6: 6 | Y6: 45476 | Z6: Completed | AA6: Returning | AB6: High | AC6: Yes | AD6: 1 | AE6: Vikram | AF6: Yadav | AM6: Needs Improvement | AN6: Medium | AO6: No | AP6: No | AQ6: 0.22647141 | AS6: 196 | AT6: 2098.648 | AU6: East | AV6: Office Supplies | AW6: 411335 | BD6: 7518642.5
A7: ORD10619 | B7: 26-08-2024 | C7: CUST1160 | D7: Neha Chopra | E7: Consumer | F7: Bengaluru | G7: Karnataka | H7: North | I7: Clothing | J7: T-Shirt | K7: 8 | L7: 3500 | M7: 0.2 | N7: 22400 | O7: 13844.24 | P7: 8555.76 | Q7: 38.2 | R7: UPI | S7: Marketplace | T7: Manish | U7: August | V7: 2024 | W7: Monday | X7: 1 | Y7: 27-08-2024 | Z7: Pending | AA7: VIP | AB7: Medium | AC7: Yes | AD7: 3 | AE7: Neha | AF7: Chopra | AM7: Good | AN7: Medium | AO7: No | AP7: Yes | AQ7: 0.38195357
A8: ORD10096 | B8: 23-10-2024 | C8: CUST1208 | D8: Priya Malhotra | E8: Consumer | F8: Lucknow | G8: Uttar Pradesh | H8: North | I8: Clothing | J8: T-Shirt | K8: 1 | L8: 2500 | M8: 0.2 | N8: 2000 | O8: 1232.23 | P8: 767.77 | Q8: 38.39 | R8: Debit Card | S8: Retail Store | T8: Kavita | U8: October | V8: 2024 | W8: Wednesday | X8: 5 | Y8: 28-10-2024 | Z8: Pending | AA8: Returning | AB8: Medium | AC8: Yes | AD8: 3 | AE8: Priya | AF8: Malhotra | AM8: Good | AN8: Low | AO8: No | AP8: No | AQ8: 0.383885
A9: ORD10080 | B9: 23-07-2024 | C9: CUST1027 | D9: Kavya Chopra | E9: Corporate | F9: Pune | G9: Maharashtra | H9: North | I9: Clothing | J9: T-Shirt | K9: 9 | L9: 2500 | M9: 0.05 | N9: 21375 | O9: 16794.56 | P9: 4580.44 | Q9: 21.43 | R9: Net Banking | S9: Online | T9: Sneha | U9: July | V9: 2024 | W9: Tuesday | X9: 10 | Y9: 45330 | Z9: Completed | AA9: New | AB9: Low | AC9: No | AD9: 4 | AE9: Kavya | AF9: Chopra | AM9: Needs Improvement | AN9: Medium | AO9: No | AP9: Yes | AQ9: 0.21428959
A10: ORD10515 | B10: 45297 | C10: CUST1229 | D10: Kavya Chopra | E10: Consumer | F10: Pune | G10: Maharashtra | H10: North | I10: Clothing | J10: Jacket | K10: 5 | L10: 700 | M10: 0 | N10: 3500 | O10: 2064.65 | P10: 1435.35 | Q10: 41.01 | R10: Net Banking | S10: Retail Store | T10: Sneha | U10: June | V10: 2024 | W10: Saturday | X10: 3 | Y10: 45388 | Z10: Completed | AA10: New | AB10: Low | AC10: No | AD10: 2 | AE10: Kavya | AF10: Chopra | AM10: Good | AN10: Low | AO10: No | AP10: No | AQ10: 0.4101
A11: ORD10955 | B11: 22-08-2024 | C11: CUST1346 | D11: Ishita Gupta | E11: Consumer | F11: Mumbai | G11: Maharashtra | H11: North | I11: Clothing | J11: Jacket | K11: 10 | L11: 3500 | M11: 0.1 | N11: 31500 | O11: 23234.21 | P11: 8265.79 | Q11: 26.24 | R11: Debit Card | S11: Online | T11: Sneha | U11: August | V11: 2024 | W11: Thursday | X11: 1 | Y11: 23-08-2024 | Z11: Completed | AA11: New | AB11: Medium | AC11: No | AD11: 4 | AE11: Ishita | AF11: Gupta | AM11: Needs Improvement | AN11: High | AO11: No | AP11: Yes | AQ11: 0.26240603
A12: ORD10593 | B12: 22-04-2025 | C12: CUST1285 | D12: Rahul Mehta | E12: Consumer | F12: Bengaluru | G12: Karnataka | H12: North | I12: Clothing | J12: Shoes | K12: 1 | L12: 2500 | M12: 0 | N12: 2500 | O12: 1699.14 | P12: 800.86 | Q12: 32.03 | R12: UPI | S12: Marketplace | T12: Anjali | U12: April | V12: 2025 | W12: Tuesday | X12: 1 | Y12: 23-04-2025 | Z12: Completed | AA12: Returning | AB12: Low | AC12: No | AD12: 2 | AE12: Rahul | AF12: Mehta | AM12: Good | AN12: Low | AO12: No | AP12: Yes | AQ12: 0.320344
A13: ORD10070 | B13: 21-12-2025 | C13: CUST1343 | D13: Sneha Verma | E13: Corporate | F13: Jaipur | G13: Rajasthan | H13: North | I13: Clothing | J13: Jeans | K13: 3 | L13: 2500 | M13: 0.2 | N13: 6000 | O13: 4205.13 | P13: 1794.87 | Q13: 29.91 | R13: Cash | S13: Online | T13: Rohit | U13: December | V13: 2025 | W13: Sunday | X13: 4 | Y13: 25-12-2025 | Z13: Cancelled | AA13: New | AB13: Medium | AC13: No | AD13: 5 | AE13: Sneha | AF13: Verma | AM13: Needs Improvement | AN13: Low | AO13: No | AP13: Yes | AQ13: 0.299145
A14: ORD10511 | B14: 21-10-2025 | C14: CUST1043 | D14: Ananya Gupta | E14: Small Business | F14: Mumbai | G14: Maharashtra | H14: North | I14: Clothing | J14: Shoes | K14: 1 | L14: 700 | M14: 0 | N14: 700 | O14: 431.94 | P14: 268.06 | Q14: 38.29 | R14: Credit Card | S14: Online | T14: Anjali | U14: October | V14: 2025 | W14: Tuesday | X14: 1 | Y14: 22-10-2025 | Z14: Completed | AA14: VIP | AB14: Medium | AC14: Yes | AD14: 2 | AE14: Ananya | AF14: Gupta | AM14: Good | AN14: Low | AO14: No | AP14: Yes | AQ14: 0.38294286
A15: ORD10972 | B15: 20-09-2025 | C15: CUST1241 | D15: Vivaan Kapoor | E15: Small Business | F15: Delhi | G15: Delhi | H15: North | I15: Clothing | J15: T-Shirt | K15: 6 | L15: 700 | M15: 0.15 | N15: 3570 | O15: 2708.04 | P15: 861.96 | Q15: 24.14 | R15: UPI | S15: Marketplace | T15: Rahul | U15: September | V15: 2025 | W15: Saturday | X15: 10 | Y15: 30-09-2025 | Z15: Completed | AA15: Returning | AB15: Medium | AC15: Yes | AD15: 3 | AE15: Vivaan | AF15: Kapoor | AM15: Needs Improvement | AN15: Low | AO15: No | AP15: Yes | AQ15: 0.24144538
A16: ORD10617 | B16: 20-02-2025 | C16: CUST1274 | D16: Meera Singh | E16: Corporate | F16: Jaipur | G16: Rajasthan | H16: North | I16: Clothing | J16: Jacket | K16: 7 | L16: 700 | M16: 0.05 | N16: 4655 | O16: 3167.75 | P16: 1487.25 | Q16: 31.95 | R16: Cash | S16: Marketplace | T16: Kavita | U16: February | V16: 2025 | W16: Thursday | X16: 9 | Y16: 45660 | Z16: Completed | AA16: Returning | AB16: High | AC16: Yes | AD16: 4 | AE16: Meera | AF16: Singh | AM16: Good | AN16: Low | AO16: No | AP16: Yes | AQ16: 0.31949517
A17: ORD10374 | B17: 19-04-2024 | C17: CUST1226 | D17: Ishita Kumar | E17: Small Business | F17: Lucknow | G17: Uttar Pradesh | H17: North | I17: Clothing | J17: Jeans | K17: 7 | L17: 1200 | M17: 0.05 | N17: 7980 | O17: 6478.8 | P17: 1501.2 | Q17: 18.81 | R17: Cash | S17: Marketplace | T17: Vikas | U17: April | V17: 2024 | W17: Friday | X17: 3 | Y17: 22-04-2024 | Z17: Completed | AA17: VIP | AB17: Low | AC17: No | AD17: 5 | AE17: Ishita | AF17: Kumar | AM17: Needs Improvement | AN17: Low | AO17: No | AP17: Yes | AQ17: 0.1881203
A18: ORD10766 | B18: 18-03-2025 | C18: CUST1007 | D18: Nisha Saxena | E18: Consumer | F18: Mumbai | G18: Maharashtra | H18: North | I18: Clothing | J18: Shoes | K18: 1 | L18: 700 | M18: 0.15 | N18: 595 | O18: 355.37 | P18: 239.63 | Q18: 40.27 | R18: UPI | S18: Marketplace | T18: Sneha | U18: March | V18: 2025 | W18: Tuesday | X18: 8 | Y18: 26-03-2025 | Z18: Pending | AA18: VIP | AB18: Medium | AC18: Yes | AD18: 3 | AE18: Nisha | AF18: Saxena | AM18: Good | AN18: Low | AO18: No | AP18: Yes | AQ18: 0.4027395
A19: ORD10037 | B19: 17-07-2025 | C19: CUST1139 | D19: Priya Kumar | E19: Consumer | F19: Chennai | G19: Tamil Nadu | H19: North | I19: Clothing | J19: T-Shirt | K19: 9 | L19: 1800 | M19: 0.15 | N19: 13770 | O19: 10186.64 | P19: 3583.36 | Q19: 26.02 | R19: Debit Card | S19: Retail Store | T19: Neeraj | U19: July | V19: 2025 | W19: Thursday | X19: 6 | Y19: 23-07-2025 | Z19: Completed | AA19: VIP | AB19: High | AC19: Yes | AD19: 2 | AE19: Priya | AF19: Kumar | AM19: Needs Improvement | AN19: Medium | AO19: No | AP19: No | AQ19: 0.26022948
A20: ORD10293 | B20: 16-09-2025 | C20: CUST1001 | D20: Arjun Sharma | E20: Corporate | F20: Lucknow | G20: Uttar Pradesh | H20: North | I20: Clothing | J20: T-Shirt | K20: 8 | L20: 2500 | M20: 0.05 | N20: 19000 | O20: 15473.59 | P20: 3526.41 | Q20: 18.56 | R20: Debit Card | S20: Marketplace | T20: Kavita | U20: September | V20: 2025 | W20: Tuesday | X20: 4 | Y20: 20-09-2025 | Z20: Completed | AA20: Returning | AB20: Low | AC20: No | AD20: 3 | AE20: Arjun | AF20: Sharma | AM20: Needs Improvement | AN20: Medium | AO20: No | AP20: Yes | AQ20: 0.18560053
A21: ORD10980 | B21: 15-03-2024 | C21: CUST1192 | D21: Aarav Malhotra | E21: Consumer | F21: Pune | G21: Maharashtra | H21: North | I21: Clothing | J21: Jeans | K21: 2 | L21: 1200 | M21: 0.15 | N21: 2040 | O21: 1631.05 | P21: 408.95 | Q21: 20.05 | R21: UPI | S21: Marketplace | T21: Amit | U21: March | V21: 2024 | W21: Friday | X21: 7 | Y21: 22-03-2024 | Z21: Cancelled | AA21: New | AB21: Low | AC21: No | AD21: 1 | AE21: Aarav | AF21: Malhotra | AM21: Needs Improvement | AN21: Low | AO21: No | AP21: Yes | AQ21: 0.20046569
A22: ORD10273 | B22: 45326 | C22: CUST1202 | D22: Rohan Gupta | E22: Corporate | F22: Delhi | G22: Delhi | H22: North | I22: Clothing | J22: Shoes | K22: 10 | L22: 3500 | M22: 0.2 | N22: 28000 | O22: 17590.76 | P22: 10409.24 | Q22: 37.18 | R22: Cash | S22: Marketplace | T22: Amit | U22: April | V22: 2024 | W22: Tuesday | X22: 4 | Y22: 45447 | Z22: Pending | AA22: VIP | AB22: Medium | AC22: No | AD22: 1 | AE22: Rohan | AF22: Gupta | AM22: Good | AN22: Medium | AO22: No | AP22: Yes | AQ22: 0.37175857
A23: ORD10452 | B23: 13-09-2025 | C23: CUST1274 | D23: Pooja Gupta | E23: Consumer | F23: Bengaluru | G23: Karnataka | H23: North | I23: Clothing | J23: Jacket | K23: 3 | L23: 1200 | M23: 0 | N23: 3600 | O23: 2265.91 | P23: 1334.09 | Q23: 37.06 | R23: UPI | S23: Online | T23: Rohit | U23: September | V23: 2025 | W23: Saturday | X23: 2 | Y23: 15-09-2025 | Z23: Completed | AA23: Returning | AB23: Low | AC23: Yes | AD23: 1 | AE23: Pooja | AF23: Gupta | AM23: Good | AN23: Low | AO23: No | AP23: Yes | AQ23: 0.37058056
A24: ORD10658 | B24: 13-04-2025 | C24: CUST1103 | D24: Neha Gupta | E24: Corporate | F24: Lucknow | G24: Uttar Pradesh | H24: North | I24: Clothing | J24: T-Shirt | K24: 9 | L24: 1200 | M24: 0.05 | N24: 10260 | O24: 6128.37 | P24: 4131.63 | Q24: 40.27 | R24: Credit Card | S24: Online | T24: Manish | U24: April | V24: 2025 | W24: Sunday | X24: 6 | Y24: 19-04-2025 | Z24: Completed | AA24: Returning | AB24: Medium | AC24: Yes | AD24: 5 | AE24: Neha | AF24: Gupta | AM24: Good | AN24: Medium | AO24: No | AP24: Yes | AQ24: 0.40269298
A25: ORD10178 | B25: 13-03-2025 | C25: CUST1321 | D25: Simran Malhotra | E25: Consumer | F25: Ahmedabad | G25: Gujarat | H25: North | I25: Clothing | J25: Jeans | K25: 1 | L25: 1800 | M25: 0 | N25: 1800 | O25: 1390.41 | P25: 409.59 | Q25: 22.75 | R25: Credit Card | S25: Online | T25: Pooja | U25: March | V25: 2025 | W25: Thursday | X25: 2 | Y25: 15-03-2025 | Z25: Completed | AA25: VIP | AB25: Medium | AC25: Yes | AD25: 4 | AE25: Simran | AF25: Malhotra | AM25: Needs Improvement | AN25: Low | AO25: No | AP25: Yes | AQ25: 0.22755
A26: ORD10556 | B26: 13-02-2025 | C26: CUST1085 | D26: Priya Chopra | E26: Small Business | F26: Chennai | G26: Tamil Nadu | H26: North | I26: Clothing | J26: Shoes | K26: 10 | L26: 3500 | M26: 0.05 | N26: 33250 | O26: 20781.79 | P26: 12468.21 | Q26: 37.5 | R26: Debit Card | S26: Retail Store | T26: Neeraj | U26: February | V26: 2025 | W26: Thursday | X26: 4 | Y26: 17-02-2025 | Z26: Completed | AA26: VIP | AB26: Low | AC26: Yes | AD26: 1 | AE26: Priya | AF26: Chopra | AM26: Good | AN26: High | AO26: Yes | AP26: No | AQ26: 0.37498376
A27: ORD10316 | B27: 13-01-2024 | C27: CUST1162 | D27: Meera Mishra | E27: Consumer | F27: Kolkata | G27: West Bengal | H27: North | I27: Clothing | J27: Jacket | K27: 3 | L27: 3500 | M27: 0.15 | N27: 8925 | O27: 5829.28 | P27: 3095.72 | Q27: 34.69 | R27: Net Banking | S27: Marketplace | T27: Vikas | U27: January | V27: 2024 | W27: Saturday | X27: 5 | Y27: 18-01-2024 | Z27: Pending | AA27: Returning | AB27: High | AC27: No | AD27: 3 | AE27: Meera | AF27: Mishra | AM27: Good | AN27: Low | AO27: No | AP27: Yes | AQ27: 0.34685938
A28: ORD10919 | B28: 46000 | C28: CUST1207 | D28: Arjun Gupta | E28: Consumer | F28: Jaipur | G28: Rajasthan | H28: North | I28: Clothing | J28: Shoes | K28: 3 | L28: 700 | M28: 0 | N28: 2100 | O28: 1218.91 | P28: 881.09 | Q28: 41.96 | R28: Credit Card | S28: Marketplace | T28: Amit | U28: September | V28: 2025 | W28: Friday | X28: 2 | Y28: 14-09-2025 | Z28: Completed | AA28: Returning | AB28: Low | AC28: No | AD28: 5 | AE28: Arjun | AF28: Gupta | AM28: Good | AN28: Low | AO28: No | AP28: Yes | AQ28: 0.41956667
A29: ORD10223 | B29: 45973 | C29: CUST1187 | D29: Neha Mehta | E29: Consumer | F29: Chennai | G29: Tamil Nadu | H29: North | I29: Clothing | J29: Shoes | K29: 6 | L29: 3500 | M29: 0.1 | N29: 18900 | O29: 13281.01 | P29: 5618.99 | Q29: 29.73 | R29: UPI | S29: Online | T29: Rahul | U29: December | V29: 2025 | W29: Thursday | X29: 10 | Y29: 21-12-2025 | Z29: Completed | AA29: VIP | AB29: High | AC29: No | AD29: 3 | AE29: Neha | AF29: Mehta | AM29: Needs Improvement | AN29: Medium | AO29: No | AP29: Yes | AQ29: 0.29730106
A30: ORD10242 | B30: 45940 | C30: CUST1212 | D30: Sneha Kapoor | E30: Small Business | F30: Delhi | G30: Delhi | H30: North | I30: Clothing | J30: Shirt | K30: 5 | L30: 700 | M30: 0.15 | N30: 2975 | O30: 2278.98 | P30: 696.02 | Q30: 23.4 | R30: UPI | S30: Online | T30: Sneha | U30: October | V30: 2025 | W30: Friday | X30: 4 | Y30: 14-10-2025 | Z30: Completed | AA30: New | AB30: Medium | AC30: No | AD30: 1 | AE30: Sneha | AF30: Kapoor | AM30: Needs Improvement | AN30: Low | AO30: No | AP30: Yes | AQ30: 0.2339563
A31: ORD10813 | B31: 45931 | C31: CUST1085 | D31: Priya Jain | E31: Consumer | F31: Delhi | G31: Delhi | H31: North | I31: Clothing | J31: Jeans | K31: 1 | L31: 1200 | M31: 0.1 | N31: 1080 | O31: 619.52 | P31: 460.48 | Q31: 42.64 | R31: Net Banking | S31: Online | T31: Amit | U31: January | V31: 2025 | W31: Friday | X31: 6 | Y31: 16-01-2025 | Z31: Cancelled | AA31: VIP | AB31: Low | AC31: Yes | AD31: 2 | AE31: Priya | AF31: Jain | AM31: Good | AN31: Low | AO31: No | AP31: Yes | AQ31: 0.42637037
A32: ORD10785 | B32: 45849 | C32: CUST1047 | D32: Kavya Jain | E32: Small Business | F32: Jaipur | G32: Rajasthan | H32: North | I32: Clothing | J32: T-Shirt | K32: 9 | L32: 3500 | M32: 0.2 | N32: 25200 | O32: 17053.31 | P32: 8146.69 | Q32: 32.33 | R32: UPI | S32: Marketplace | T32: Sneha | U32: November | V32: 2025 | W32: Friday | X32: 10 | Y32: 17-11-2025 | Z32: Completed | AA32: Returning | AB32: Medium | AC32: Yes | AD32: 3 | AE32: Kavya | AF32: Jain | AM32: Good | AN32: Medium | AO32: No | AP32: Yes | AQ32: 0.32328135
A33: ORD10031 | B33: 45841 | C33: CUST1277 | D33: Vivaan Jain | E33: Consumer | F33: Hyderabad | G33: Telangana | H33: North | I33: Clothing | J33: Jacket | K33: 6 | L33: 2500 | M33: 0.1 | N33: 13500 | O33: 9139.27 | P33: 4360.73 | Q33: 32.3 | R33: Credit Card | S33: Online | T33: Rahul | U33: March | V33: 2025 | W33: Friday | X33: 5 | Y33: 45994 | Z33: Completed | AA33: New | AB33: Low | AC33: Yes | AD33: 2 | AE33: Vivaan | AF33: Jain | AM33: Good | AN33: Medium | AO33: No | AP33: Yes | AQ33: 0.32301704
A34: ORD10009 | B34: 45331 | C34: CUST1041 | D34: Aditya Yadav | E34: Corporate | F34: Chennai | G34: Tamil Nadu | H34: North | I34: Clothing | J34: Shirt | K34: 2 | L34: 1800 | M34: 0.1 | N34: 3240 | O34: 2550.08 | P34: 689.92 | Q34: 21.29 | R34: Net Banking | S34: Online | T34: Pooja | U34: September | V34: 2024 | W34: Monday | X34: 1 | Y34: 45360 | Z34: Completed | AA34: VIP | AB34: Medium | AC34: Yes | AD34: 3 | AE34: Aditya | AF34: Yadav | AM34: Needs Improvement | AN34: Low | AO34: No | AP34: Yes | AQ34: 0.21293827
A35: ORD10893 | B35: 45815 | C35: CUST1232 | D35: Ananya Mehta | E35: Consumer | F35: Ahmedabad | G35: Gujarat | H35: North | I35: Clothing | J35: Shoes | K35: 7 | L35: 2500 | M35: 0.05 | N35: 16625 | O35: 13335.81 | P35: 3289.19 | Q35: 19.78 | R35: Cash | S35: Retail Store | T35: Manish | U35: July | V35: 2025 | W35: Sunday | X35: 3 | Y35: 45907 | Z35: Completed | AA35: VIP | AB35: Medium | AC35: No | AD35: 5 | AE35: Ananya | AF35: Mehta | AM35: Needs Improvement | AN35: Medium | AO35: No | AP35: No | AQ35: 0.19784602
A36: ORD10763 | B36: 45813 | C36: CUST1342 | D36: Vikram Verma | E36: Small Business | F36: Chennai | G36: Tamil Nadu | H36: North | I36: Clothing | J36: Shoes | K36: 10 | L36: 1200 | M36: 0.15 | N36: 10200 | O36: 6395.83 | P36: 3804.17 | Q36: 37.3 | R36: Credit Card | S36: Online | T36: Manish | U36: May | V36: 2025 | W36: Tuesday | X36: 9 | Y36: 15-05-2025 | Z36: Cancelled | AA36: New | AB36: Low | AC36: No | AD36: 1 | AE36: Vikram | AF36: Verma | AM36: Good | AN36: Medium | AO36: No | AP36: Yes | AQ36: 0.37295784
A37: ORD10440 | B37: 45812 | C37: CUST1255 | D37: Neha Kumar | E37: Corporate | F37: Delhi | G37: Delhi | H37: North | I37: Clothing | J37: T-Shirt | K37: 10 | L37: 1800 | M37: 0.15 | N37: 15300 | O37: 10104.38 | P37: 5195.62 | Q37: 33.96 | R37: Debit Card | S37: Retail Store | T37: Rahul | U37: April | V37: 2025 | W37: Sunday | X37: 8 | Y37: 14-04-2025 | Z37: Pending | AA37: Returning | AB37: High | AC37: Yes | AD37: 3 | AE37: Neha | AF37: Kumar | AM37: Good | AN37: Medium | AO37: No | AP37: No | AQ37: 0.33958301
A38: ORD10004 | B38: 45778 | C38: CUST1024 | D38: Vikram Agarwal | E38: Corporate | F38: Mumbai | G38: Maharashtra | H38: North | I38: Clothing | J38: Shirt | K38: 9 | L38: 1800 | M38: 0.2 | N38: 12960 | O38: 9593.44 | P38: 3366.56 | Q38: 25.98 | R38: Debit Card | S38: Online | T38: Kavita | U38: January | V38: 2025 | W38: Sunday | X38: 10 | Y38: 15-01-2025 | Z38: Completed | AA38: Returning | AB38: Medium | AC38: No | AD38: 2 | AE38: Vikram | AF38: Agarwal | AM38: Needs Improvement | AN38: Medium | AO38: No | AP38: Yes | AQ38: 0.25976543
A39: ORD10329 | B39: 45697 | C39: CUST1046 | D39: Priya Jain | E39: Corporate | F39: Jaipur | G39: Rajasthan | H39: North | I39: Clothing | J39: Jeans | K39: 3 | L39: 3500 | M39: 0 | N39: 10500 | O39: 7510.16 | P39: 2989.84 | Q39: 28.47 | R39: Net Banking | S39: Online | T39: Rahul | U39: September | V39: 2025 | W39: Tuesday | X39: 3 | Y39: 45786 | Z39: Pending | AA39: New | AB39: High | AC39: Yes | AD39: 5 | AE39: Priya | AF39: Jain | AM39: Needs Improvement | AN39: Medium | AO39: No | AP39: Yes | AQ39: 0.28474667
A40: ORD10445 | B40: 45662 | C40: CUST1232 | D40: Priya Verma | E40: Consumer | F40: Hyderabad | G40: Telangana | H40: North | I40: Clothing | J40: Shirt | K40: 9 | L40: 2500 | M40: 0.05 | N40: 21375 | O40: 15043.06 | P40: 6331.94 | Q40: 29.62 | R40: Net Banking | S40: Online | T40: Amit | U40: May | V40: 2025 | W40: Thursday | X40: 2 | Y40: 45721 | Z40: Completed | AA40: VIP | AB40: High | AC40: No | AD40: 1 | AE40: Priya | AF40: Verma | AM40: Needs Improvement | AN40: Medium | AO40: No | AP40: Yes | AQ40: 0.29623111
A41: ORD10375 | B41: 45662 | C41: CUST1311 | D41: Vivaan Chopra | E41: Small Business | F41: Kolkata | G41: West Bengal | H41: North | I41: Clothing | J41: Jeans | K41: 5 | L41: 1200 | M41: 0.1 | N41: 5400 | O41: 3000.73 | P41: 2399.27 | Q41: 44.43 | R41: Debit Card | S41: Retail Store | T41: Anjali | U41: May | V41: 2025 | W41: Thursday | X41: 6 | Y41: 45843 | Z41: Completed | AA41: Returning | AB41: Medium | AC41: No | AD41: 1 | AE41: Vivaan | AF41: Chopra | AM41: Good | AN41: Low | AO41: No | AP41: No | AQ41: 0.44430926
...

Sheet Dashboard
S1: Total Sales | U1: Total aprofit | W1: Total Orders | Y1: Average Order Value | AA1: Sumproduct
A2: Region | B2: Sum of Sales | S2: =SUM(Sheet1!N2:N1001) -> 30311250 | U2: =SUM(Sheet1!P2:P1001) -> 9519984.1 | W2: =COUNTA(Sheet1!A2:A1001) -> 1000 | Y2: =AVERAGE(Sheet1!N2:N1001) -> 30311.25 | AA2: =SUMPRODUCT(Sheet1!K2:K1001,Sheet1!L2:L1001) -> 33700500
A3: North | B3: 5965332.5
A4: Grand Total | B4: 5965332.5 | S4: Top Product | U4: Top salesperson
S5: Watch | U5: Vikas
A21: Category | B21: Sum of Sales
A22: Accessories | B22: 348330
A23: Clothing | B23: 490985
A24: Electronics | B24: 3481750
A25: Furniture | B25: 1519200
A26: Office Supplies | B26: 125067.5
A27: Grand Total | B27: 5965332.5
A40: Product | B40: Sum of Sales
A41: Watch | B41: 60020
A42: Wallet | B42: 43680
A43: T-Shirt | B43: 150785
A44: Tablet | B44: 580700
A45: Table | B45: 383400
A46: Sunglasses | B46: 81185
A47: Stapler | B47: 6720
A48: Sofa | B48: 311500
A49: Smartphone | B49: 501950
A50: Shoes | B50: 124270
A51: Shirt | B51: 62150
A52: Printer Paper | B52: 38537.5
... A66: Grand Total | B66: 5965332.5
A72: Category | B72: Sum of Profit
A73: Accessories | B73: 104830.38
A74: Clothing | B74: 153730.63
A75: Electronics | B75: 1065908.1
A76: Furniture | B76: 481396.74
A77: Office Supplies | B77: 38664.94
A78: Grand Total | B78: 1844530.8
A86: Month | B86: Sum of Sales
A87: January | B87: 363005
A88: February | B88: 450610
A89: March | B89: 562725
A90: April | B90: 341137.5
A91: May | B91: 146860
A92: June | B92: 659850
...

Sheet Sheet1
A1: Order_ID | B1: Order_Date | C1: Customer_ID | D1: Customer_Name | E1: Customer_Segment | F1: City | G1: State | H1: Region | I1: Category | J1: Product | K1: Quantity | L1: Unit_Price | M1: Discount | N1: Sales | O1: Cost | P1: Profit | Q1: Profit_Margin_% | R1: Payment_Method | S1: Sales_Channel | T1: Salesperson | U1: Month | V1: Year | W1: Day_Name | X1: Delivery_Days | Y1: Delivery_Date | Z1: Order_Status | AA1: Customer_Type | AB1: Priority | AC1: Return_Requested | AD1: Rating | AE1: First_name | AF1: Last_Name | AG1: SUM | AH1: Average | AI1: Count | AJ1: Counta | AK1: MIN | AL1: Max | AM1: IF | AN1: IFS | AO1: AND | AP1: OR | AQ1: IFERROR | AR1: COUNTIFS | AS1: AVERAGEIFS | AT1: Region-wise Sales | AU1: Category-wise Sales | AV1: Total Sales | AW1: Region_Total_Sales | AX1: Performance
A2: ORD10146 | B2: 45294 | C2: CUST1306 | D2: Aditi Gupta | E2: Corporate | F2: Kolkata | G2: West Bengal | H2: East | I2: Furniture | J2: Table | K2: 3 | L2: 4000 | M2: 0.05 | N2: 11400 | O2: 7908.36 | P2: 3491.64 | Q2: 30.63 | R2: UPI | S2: Marketplace | T2: Sneha | U2: March | V2: 2024 | W2: Friday | X2: 10 | Y2: 45599 | Z2: Completed | AA2: VIP | AB2: High | AC2: Yes | AD2: 2 | AE2: Aditi | AF2: Gupta | AG2: =SUM(N2:N1001) -> 30311250 | AH2: =AVERAGE(N2:N1001) -> 30311.25 | AI2: =COUNT(N2:N1001) -> 1000 | AJ2: =COUNTA(N2:N1001) -> 1000 | AK2: =MIN(N2:N1001) -> 95 | AL2: =MAX(N2:N1001) -> 450000 | AM2: =IF(Q2>=30,"Good","Needs Improvement") -> Good | AN2: {=_xlfn.IFS(N2<10000,"Low",N2<30000,"Medium",N2>=30000,"High")} -> Medium | AO2: =IF(AND(N2>=30000,P2>=10000),"Yes","No") -> No | AP2: =IF(OR(S2="Online",S2="Marketplace"),"Yes","No") -> Yes | AQ2: =IFERROR(P2/N2,"No Error") -> 0.30628421 | AR2: =COUNTIFS($I$2:$I$1001,AU2) -> 188 | AS2: =AVERAGEIFS($N$2:$N$1001,$I$2:$I$1001,AU2) -> 105143.62 | AT2: North | AU2: Electronics | AV2: =SUMIFS($N$2:$N$1001,$I$2:$I$1001,AU2) -> 19767000 | AW2: =SUMIFS($N$2:$N$1001,$H$2:$H$1001,AT2) -> 5965332.5 | AX2: =IF(P2>=20000,"Excellent",IF(P2>=10000,"Good",IF(P2>=5000,"Average","Low"))) -> Low
A3: ORD10172 | B3: 45294 | C3: CUST1073 | D3: Arjun Chopra | E3: Small Business | F3: Lucknow | G3: Uttar Pradesh | H3: East | I3: Furniture | J3: Desk | K3: 6 | L3: 4000 | M3: 0.1 | N3: 21600 | O3: 15301.1 | P3: 6298.9 | Q3: 29.16 | R3: Credit Card | S3: Retail Store | T3: Kavita | U3: March | V3: 2024 | W3: Friday | X3: 1 | Y3: 45325 | Z3: Completed | AA3: VIP | AB3: Low | AC3: No | AD3: 3 | AE3: Arjun | AF3: Chopra | AM3: =IF(Q3>=30,"Good","Needs Improvement") -> Needs Improvement | AN3: {=_xlfn.IFS(N3<10000,"Low",N3<30000,"Medium",N3>=30000,"High")} -> Medium | AO3: =IF(AND(N3>=30000,P3>=10000),"Yes","No") -> No | AP3: =IF(OR(S3="Online",S3="Marketplace"),"Yes","No") -> No | AQ3: =IFERROR(P3/N3,"No Error") -> 0.29161574 | AR3: =COUNTIFS($I$2:$I$1001,AU3) -> 205 | AS3: =AVERAGEIFS($N$2:$N$1001,$I$2:$I$1001,AU3) -> 33072.195 | AT3: South | AU3: Furniture | AV3: =SUMIFS($N$2:$N$1001,$I$2:$I$1001,AU3) -> 6779800 | AW3: =SUMIFS($N$2:$N$1001,$H$2:$H$1001,AT3) -> 8560317.5 | AX3: =IF(P3>=20000,"Excellent",IF(P3>=10000,"Good",IF(P3>=5000,"Average","Low"))) -> Average
A4: ORD10477 | B4: 45294 | C4: CUST1108 | D4: Vikram Yadav | E4: Small Business | F4: Lucknow | G4: Uttar Pradesh | H4: North | I4: Clothing | J4: Jeans | K4: 8 | L4: 1800 | M4: 0.15 | N4: 12240 | O4: 9467.99 | P4: 2772.01 | Q4: 22.65 | R4: Debit Card | S4: Retail Store | T4: Kavita | U4: March | V4: 2024 | W4: Friday | X4: 6 | Y4: 45476 | Z4: Completed | AA4: Returning | AB4: High | AC4: Yes | AD4: 1 | AE4: Vikram | AF4: Yadav | AM4: =IF(Q4>=30,"Good","Needs Improvement") -> Needs Improvement | AN4: {=_xlfn.IFS(N4<10000,"Low",N4<30000,"Medium",N4>=30000,"High")} -> Medium | AO4: =IF(AND(N4>=30000,P4>=10000),"Yes","No") -> No | AP4: =IF(OR(S4="Online",S4="Marketplace"),"Yes","No") -> No | AQ4: =IFERROR(P4/N4,"No Error") -> 0.22647141 | AR4: =COUNTIFS($I$2:$I$1001,AU4) -> 196 | AS4: =AVERAGEIFS($N$2:$N$1001,$I$2:$I$1001,AU4) -> 2098.648 | AT4: East | AU4: Office Supplies | AV4: =SUMIFS($N$2:$N$1001,$I$2:$I$1001,AU4) -> 411335 | AW4: =SUMIFS($N$2:$N$1001,$H$2:$H$1001,AT4) -> 7518642.5 | AX4: =IF(P4>=20000,"Excellent",IF(P4>=10000,"Good",IF(P4>=5000,"Average","Low"))) -> Low
A5: ORD10927 | B5: 45294 | C5: CUST1107 | D5: Aarav Agarwal | E5: Small Business | F5: Jaipur | G5: Rajasthan | H5: West | I5: Clothing | J5: Shirt | K5: 2 | L5: 700 | M5: 0.2 | N5: 1120 | O5: 653.09 | P5: 466.91 | Q5: 41.69 | R5: Net Banking | S5: Online | T5: Neeraj | U5: March | V5: 2024 | W5: Friday | X5: 2 | Y5: 45354 | Z5: Cancelled | AA5: Returning | AB5: Medium | AC5: No | AD5: 1 | AE5: Aarav | AF5: Agarwal | AM5: =IF(Q5>=30,"Good","Needs Improvement") -> Good | AN5: {=_xlfn.IFS(N5<10000,"Low",N5<30000,"Medium",N5>=30000,"High")} -> Low | AO5: =IF(AND(N5>=30000,P5>=10000),"Yes","No") -> No | AP5: =IF(OR(S5="Online",S5="Marketplace"),"Yes","No") -> Yes | AQ5: =IFERROR(P5/N5,"No Error") -> 0.41688393 | AR5: =COUNTIFS($I$2:$I$1001,AU5) -> 195 | AS5: =AVERAGEIFS($N$2:$N$1001,$I$2:$I$1001,AU5) -> 9673.6923 | AT5: West | AU5: Clothing | AV5: =SUMIFS($N$2:$N$1001,$I$2:$I$1001,AU5) -> 1886370 | AW5: =SUMIFS($N$2:$N$1001,$H$2:$H$1001,AT5) -> 8266957.5 | AX5: =IF(P5>=20000,"Excellent",IF(P5>=10000,"Good",IF(P5>=5000,"Average","Low"))) -> Low
A6: ORD10497 | B6: 45296 | C6: CUST1350 | D6: Rohan Jain | E6: Corporate | F6: Chennai | G6: Tamil Nadu | H6: West | I6: Electronics | J6: Smartphone | K6: 4 | L6: 22000 | M6: 0.1 | N6: 79200 | O6: 55323.84 | P6: 23876.16 | Q6: 30.15 | R6: Debit Card | S6: Online | T6: Neeraj | U6: May | V6: 2024 | W6: Wednesday | X6: 7 | Y6: 45509 | Z6: Pending | AA6: New | AB6: Low | AC6: Yes | AD6: 3 | AE6: Rohan | AF6: Jain | AM6: =IF(Q6>=30,"Good","Needs Improvement") -> Good | AN6: {=_xlfn.IFS(N6<10000,"Low",N6<30000,"Medium",N6>=30000,"High")} -> High | AO6: =IF(AND(N6>=30000,P6>=10000),"Yes","No") -> Yes | AP6: =IF(OR(S6="Online",S6="Marketplace"),"Yes","No") -> Yes | AQ6: =IFERROR(P6/N6,"No Error") -> 0.30146667 | AR6: =COUNTIFS($I$2:$I$1001,AU6) -> 216 | AS6: =AVERAGEIFS($N$2:$N$1001,$I$2:$I$1001,AU6) -> 6790.4861 | AU6: Accessories | AV6: =SUMIFS($N$2:$N$1001,$I$2:$I$1001,AU6) -> 1466745 | AX6: =IF(P6>=20000,"Excellent",IF(P6>=10000,"Good",IF(P6>=5000,"Average","Low"))) -> Excellent
A7: ORD10605 | B7: 45296 | C7: CUST1115 | D7: Karan Kumar | E7: Corporate | F7: Lucknow | G7: Uttar Pradesh | H7: North | I7: Office Supplies | J7: Notebook | K7: 6 | L7: 350 | M7: 0.05 | N7: 1995 | O7: 1359.38 | P7: 635.62 | Q7: 31.86 | R7: Debit Card | S7: Marketplace | T7: Sneha | U7: May | V7: 2024 | W7: Wednesday | X7: 5 | Y7: 45448 | Z7: Completed | AA7: New | AB7: Low | AC7: Yes | AD7: 5 | AE7: Karan | AF7: Kumar | AM7: =IF(Q7>=30,"Good","Needs Improvement") -> Good | AN7: {=_xlfn.IFS(N7<10000,"Low",N7<30000,"Medium",N7>=30000,"High")} -> Low | AO7: =IF(AND(N7>=30000,P7>=10000),"Yes","No") -> No | AP7: =IF(OR(S7="Online",S7="Marketplace"),"Yes","No") -> Yes | AQ7: =IFERROR(P7/N7,"No Error") -> 0.31860652 | AX7: =IF(P7>=20000,"Excellent",IF(P7>=10000,"Good",IF(P7>=5000,"Average","Low"))) -> Low
A8: ORD10515 | B8: 45297 | C8: CUST1229 | D8: Kavya Chopra | E8: Consumer | F8: Pune | G8: Maharashtra | H8: North | I8: Clothing | J8: Jacket | K8: 5 | L8: 700 | M8: 0 | N8: 3500 | O8: 2064.65 | P8: 1435.35 | Q8: 41.01 | R8: Net Banking | S8: Retail Store | T8: Sneha | U8: June | V8: 2024 | W8: Saturday | X8: 3 | Y8: 45388 | Z8: Completed | AA8: New | AB8: Low | AC8: No | AD8: 2 | AE8: Kavya | AF8: Chopra | AM8: =IF(Q8>=30,"Good","Needs Improvement") -> Good | AN8: {=_xlfn.IFS(N8<10000,"Low",N8<30000,"Medium",N8>=30000,"High")} -> Low | AO8: =IF(AND(N8>=30000,P8>=10000),"Yes","No") -> No | AP8: =IF(OR(S8="Online",S8="Marketplace"),"Yes","No") -> No | AQ8: =IFERROR(P8/N8,"No Error") -> 0.4101 | AX8: =IF(P8>=20000,"Excellent",IF(P8>=10000,"Good",IF(P8>=5000,"Average","Low"))) -> Low
A9: ORD10324 | B9: 45300 | C9: CUST1277 | D9: Priya Malhotra | E9: Small Business | F9: Bengaluru | G9: Karnataka | H9: West | I9: Electronics | J9: Smartphone | K9: 1 | L9: 50000 | M9: 0.2 | N9: 40000 | O9: 22680.32 | P9: 17319.68 | Q9: 43.3 | R9: Credit Card | S9: Online | T9: Vikas | U9: September | V9: 2024 | W9: Sunday | X9: 8 | Y9: 45544 | Z9: Pending | AA9: New | AB9: Medium | AC9: Yes | AD9: 4 | AE9: Priya | AF9: Malhotra | AM9: =IF(Q9>=30,"Good","Needs Improvement") -> Good | AN9: {=_xlfn.IFS(N9<10000,"Low",N9<30000,"Medium",N9>=30000,"High")} -> High | AO9: =IF(AND(N9>=30000,P9>=10000),"Yes","No") -> Yes | AP9: =IF(OR(S9="Online",S9="Marketplace"),"Yes","No") -> Yes | AQ9: =IFERROR(P9/N9,"No Error") -> 0.432992 | AX9: =IF(P9>=20000,"Excellent",IF(P9>=10000,"Good",IF(P9>=5000,"Average","Low"))) -> Good
A10: ORD10559 | B10: 45300 | C10: CUST1116 | D10: Simran Yadav | E10: Small Business | F10: Hyderabad | G10: Telangana | H10: West | I10: Electronics | J10: Laptop | K10: 1 | L10: 35000 | M10: 0.1 | N10: 31500 | O10: 18184.28 | P10: 13315.72 | Q10: 42.27 | R10: Cash | S10: Retail Store | T10: Neeraj | U10: September | V10: 2024 | W10: Sunday | X10: 2 | Y10: 45360 | Z10: Cancelled | AA10: New | AB10: High | AC10: No | AD10: 4 | AE10: Simran | AF10: Yadav | AM10: =IF(Q10>=30,"Good","Needs Improvement") -> Good | AN10: {=_xlfn.IFS(N10<10000,"Low",N10<30000,"Medium",N10>=30000,"High")} -> High | AO10: =IF(AND(N10>=30000,P10>=10000),"Yes","No") -> Yes | AP10: =IF(OR(S10="Online",S10="Marketplace"),"Yes","No") -> No | AQ10: =IFERROR(P10/N10,"No Error") -> 0.42272127 | AX10: =IF(P10>=20000,"Excellent",IF(P10>=10000,"Good",IF(P10>=5000,"Average","Low"))) -> Good
A11: ORD10370 | B11: 45301 | C11: CUST1223 | D11: Nisha Yadav | E11: Small Business | F11: Ahmedabad | G11: Gujarat | H11: North | I11: Furniture | J11: Table | K11: 8 | L11: 4000 | M11: 0.15 | N11: 27200 | O11: 21222.78 | P11: 5977.22 | Q11: 21.98 | R11: Net Banking | S11: Online | T11: Vikas | U11: October | V11: 2024 | W11: Tuesday | X11: 9 | Y11: 45575 | Z11: Cancelled | AA11: Returning | AB11: Low | AC11: Yes | AD11: 2 | AE11: Nisha | AF11: Yadav | AM11: =IF(Q11>=30,"Good","Needs Improvement") -> Needs Improvement | AN11: {=_xlfn.IFS(N11<10000,"Low",N11<30000,"Medium",N11>=30000,"High")} -> Medium | AO11: =IF(AND(N11>=30000,P11>=10000),"Yes","No") -> No | AP11: =IF(OR(S11="Online",S11="Marketplace"),"Yes","No") -> Yes | AQ11: =IFERROR(P11/N11,"No Error") -> 0.21975074 | AX11: =IF(P11>=20000,"Excellent",IF(P11>=10000,"Good",IF(P11>=5000,"Average","Low"))) -> Average
A12: ORD10538 | B12: 45301 | C12: CUST1213 | D12: Vikram Sharma | E12: Corporate | F12: Kolkata | G12: West Bengal | H12: North | I12: Electronics | J12: Tablet | K12: 4 | L12: 35000 | M12: 0.1 | N12: 126000 | O12: 97825.23 | P12: 28174.77 | Q12: 22.36 | R12: Credit Card | S12: Online | T12: Pooja | U12: October | V12: 2024 | W12: Tuesday | X12: 5 | Y12: 45453 | Z12: Completed | AA12: Returning | AB12: High | AC12: No | AD12: 3 | AE12: Vikram | AF12: Sharma | AM12: =IF(Q12>=30,"Good","Needs Improvement") -> Needs Improvement | AN12: {=_xlfn.IFS(N12<10000,"Low",N12<30000,"Medium",N12>=30000,"High")} -> High | AO12: =IF(AND(N12>=30000,P12>=10000),"Yes","No") -> Yes | AP12: =IF(OR(S12="Online",S12="Marketplace"),"Yes","No") -> Yes | AQ12: =IFERROR(P12/N12,"No Error") -> 0.22360929 | AX12: =IF(P12>=20000,"Excellent",IF(P12>=10000,"Good",IF(P12>=5000,"Average","Low"))) -> Excellent
A13: ORD10437 | B13: 45303 | C13: CUST1144 | D13: Rohan Chopra | E13: Small Business | F13: Lucknow | G13: Uttar Pradesh | H13: West | I13: Accessories | J13: Watch | K13: 9 | L13: 1200 | M13: 0.05 | N13: 10260 | O13: 7386.73 | P13: 2873.27 | Q13: 28 | R13: Debit Card | S13: Marketplace | T13: Neeraj | U13: December | V13: 2024 | W13: Sunday | X13: 4 | Y13: 45424 | Z13: Completed | AA13: Returning | AB13: High | AC13: Yes | AD13: 2 | AE13: Rohan | AF13: Chopra | AM13: =IF(Q13>=30,"Good","Needs Improvement") -> Needs Improvement | AN13: {=_xlfn.IFS(N13<10000,"Low",N13<30000,"Medium",N13>=30000,"High")} -> Medium | AO13: =IF(AND(N13>=30000,P13>=10000),"Yes","No") -> No | AP13: =IF(OR(S13="Online",S13="Marketplace"),"Yes","No") -> Yes | AQ13: =IFERROR(P13/N13,"No Error") -> 0.28004581 | AX13: =IF(P13>=20000,"Excellent",IF(P13>=10000,"Good",IF(P13>=5000,"Average","Low"))) -> Low
A14: ORD10475 | B14: 45323 | C14: CUST1098 | D14: Pooja Mehta | E14: Corporate | F14: Lucknow | G14: Uttar Pradesh | H14: East | I14: Office Supplies | J14: Printer Paper | K14: 6 | L14: 500 | M14: 0.2 | N14: 2400 | O14: 1702.36 | P14: 697.64 | Q14: 29.07 | R14: Debit Card | S14: Marketplace | T14: Manish | U14: January | V14: 2024 | W14: Tuesday | X14: 5 | Y14: 45474 | Z14: Completed | AA14: VIP | AB14: Low | AC14: Yes | AD14: 4 | AE14: Pooja | AF14: Mehta | AM14: =IF(Q14>=30,"Good","Needs Improvement") -> Needs Improvement | AN14: {=_xlfn.IFS(N14<10000,"Low",N14<30000,"Medium",N14>=30000,"High")} -> Low | AO14: =IF(AND(N14>=30000,P14>=10000),"Yes","No") -> No | AP14: =IF(OR(S14="Online",S14="Marketplace"),"Yes","No") -> Yes | AQ14: =IFERROR(P14/N14,"No Error") -> 0.29068333 | AX14: =IF(P14>=20000,"Excellent",IF(P14>=10000,"Good",IF(P14>=5000,"Average","Low"))) -> Low
A15: ORD10714 | B15: 45323 | C15: CUST1197 | D15: Priya Sharma | E15: Small Business | F15: Delhi | G15: Delhi | H15: East | I15: Accessories | J15: Backpack | K15: 6 | L15: 500 | M15: 0.05 | N15: 2850 | O15: 1571.09 | P15: 1278.91 | Q15: 44.87 | R15: Credit Card | S15: Online | T15: Rahul | U15: January | V15: 2024 | W15: Tuesday | X15: 9 | Y15: 45597 | Z15: Completed | AA15: VIP | AB15: High | AC15: No | AD15: 2 | AE15: Priya | AF15: Sharma | AM15: =IF(Q15>=30,"Good","Needs Improvement") -> Good | AN15: {=_xlfn.IFS(N15<10000,"Low",N15<30000,"Medium",N15>=30000,"High")} -> Low | AO15: =IF(AND(N15>=30000,P15>=10000),"Yes","No") -> No | AP15: =IF(OR(S15="Online",S15="Marketplace"),"Yes","No") -> Yes | AQ15: =IFERROR(P15/N15,"No Error") -> 0.44874035 | AX15: =IF(P15>=20000,"Excellent",IF(P15>=10000,"Good",IF(P15>=5000,"Average","Low"))) -> Low
A16: ORD10115 | B16: 45324 | C16: CUST1070 | D16: Ishita Jain | E16: Corporate | F16: Chennai | G16: Tamil Nadu | H16: West | I16: Electronics | J16: Monitor | K16: 1 | L16: 8000 | M16: 0.15 | N16: 6800 | O16: 4070.45 | P16: 2729.55 | Q16: 40.14 | R16: Cash | S16: Retail Store | T16: Neeraj | U16: February | V16: 2024 | W16: Friday | X16: 5 | Y16: 45475 | Z16: Pending | AA16: VIP | AB16: High | AC16: Yes | AD16: 3 | AE16: Ishita | AF16: Jain | AM16: =IF(Q16>=30,"Good","Needs Improvement") -> Good | AN16: {=_xlfn.IFS(N16<10000,"Low",N16<30000,"Medium",N16>=30000,"High")} -> Low | AO16: =IF(AND(N16>=30000,P16>=10000),"Yes","No") -> No | AP16: =IF(OR(S16="Online",S16="Marketplace"),"Yes","No") -> No | AQ16: =IFERROR(P16/N16,"No Error") -> 0.40140441 | AX16: =IF(P16>=20000,"Excellent",IF(P16>=10000,"Good",IF(P16>=5000,"Average","Low"))) -> Low
A17: ORD10992 | B17: 45324 | C17: CUST1314 | D17: Priya Verma | E17: Consumer | F17: Lucknow | G17: Uttar Pradesh | H17: East | I17: Electronics | J17: Laptop | K17: 5 | L17: 15000 | M17: 0.05 | N17: 71250 | O17: 40064.87 | P17: 31185.13 | Q17: 43.77 | R17: Net Banking | S17: Online | T17: Rahul | U17: February | V17: 2024 | W17: Friday | X17: 4 | Y17: 45445 | Z17: Pending | AA17: VIP | AB17: Medium | AC17: Yes | AD17: 5 | AE17: Priya | AF17: Verma | AM17: =IF(Q17>=30,"Good","Needs Improvement") -> Good | AN17: {=_xlfn.IFS(N17<10000,"Low",N17<30000,"Medium",N17>=30000,"High")} -> High | AO17: =IF(AND(N17>=30000,P17>=10000),"Yes","No") -> Yes | AP17: =IF(OR(S17="Online",S17="Marketplace"),"Yes","No") -> Yes | AQ17: =IFERROR(P17/N17,"No Error") -> 0.43768604 | AX17: =IF(P17>=20000,"Excellent",IF(P17>=10000,"Good",IF(P17>=5000,"Average","Low"))) -> Excellent
A18: ORD10660 | B18: 45325 | C18: CUST1021 | D18: Sneha Mehta | E18: Small Business | F18: Mumbai | G18: Maharashtra | H18: West | I18: Accessories | J18: Belt | K18: 1 | L18: 2000 | M18: 0.15 | N18: 1700 | O18: 1315.19 | P18: 384.81 | Q18: 22.64 | R18: Cash | S18: Online | T18: Neeraj | U18: March | V18: 2024 | W18: Saturday | X18: 5 | Y18: 45476 | Z18: Pending | AA18: New | AB18: Medium | AC18: Yes | AD18: 2 | AE18: Sneha | AF18: Mehta | AM18: =IF(Q18>=30,"Good","Needs Improvement") -> Needs Improvement | AN18: {=_xlfn.IFS(N18<10000,"Low",N18<30000,"Medium",N18>=30000,"High")} -> Low | AO18: =IF(AND(N18>=30000,P18>=10000),"Yes","No") -> No | AP18: =IF(OR(S18="Online",S18="Marketplace"),"Yes","No") -> Yes | AQ18: =IFERROR(P18/N18,"No Error") -> 0.22635882 | AX18: =IF(P18>=20000,"Excellent",IF(P18>=10000,"Good",IF(P18>=5000,"Average","Low"))) -> Low
... A56: ORD10742 | B56: 45383 | C56: CUST1041 | D56: Pooja Jain | E56: Small Business | F56: Hyderabad | G56: Telangana | H56: South | I56: Electronics | J56: Smartphone | K56: 2 | L56: 50000 | M56: 0 | N56: 100000 | O56: 60675.91 | P56: 39324.09 | Q56: 39.32 | R56: Cash | S56: Online | T56: Rohit | U56: January | V56: 2024 | W56: Thursday | X56: 7 | Y56: 45597 | Z56: Completed | AA56: VIP | AB56: High | AC56: Yes | AD56: 4 | AE56: Pooja | AF56: Jain | AM56: =IF(Q56>=30,"Good","Needs Improvement") -> Good | AN56: {=_xlfn.IFS(N56<10000,"Low",N56<30000,"Medium",N56>=30000,"High")} -> High | AO56: =IF(AND(N56>=30000,P56>=10000),"Yes","No") -> Yes | AP56: =IF(OR(S56="Online",S56="Marketplace"),"Yes","No") -> Yes | AQ56: =IFERROR(P56/N56,"No Error") -> 0.3932409 | AX56: =IF(P56>=20000,"Excellent",IF(P56>=10000,"Good",IF(P56>=5000,"Average","Low"))) -> Excellent
